{"trial_id": "0001", "hyperparameters": {"space": [{"class_name": "Int", "config": {"name": "units", "default": null, "conditions": [], "min_value": 32, "max_value": 256, "step": 32, "sampling": "linear"}}, {"class_name": "Float", "config": {"name": "dropout_rate", "default": 0.0, "conditions": [], "min_value": 0.0, "max_value": 0.3, "step": 0.1, "sampling": "linear"}}, {"class_name": "Choice", "config": {"name": "learning_rate", "default": 0.0001, "conditions": [], "values": [0.0001, 0.001, 0.01], "ordered": true}}], "values": {"units": 192, "dropout_rate": 0.2, "learning_rate": 0.001, "tuner/epochs": 2, "tuner/initial_epoch": 0, "tuner/bracket": 2, "tuner/round": 0}}, "metrics": {"metrics": {}}, "score": null, "best_step": 0, "status": "FAILED", "message": "Traceback (most recent call last):\n  File \"c:\\Users\\joeyi\\AppData\\Local\\Programs\\Python\\Python311\\Lib\\site-packages\\keras_tuner\\src\\engine\\base_tuner.py\", line 274, in _try_run_and_update_trial\n    self._run_and_update_trial(trial, *fit_args, **fit_kwargs)\n  File \"c:\\Users\\joeyi\\AppData\\Local\\Programs\\Python\\Python311\\Lib\\site-packages\\keras_tuner\\src\\engine\\base_tuner.py\", line 239, in _run_and_update_trial\n    results = self.run_trial(trial, *fit_args, **fit_kwargs)\n              ^^^^^^^^^^^^^^^^^^^^^^^^^^^^^^^^^^^^^^^^^^^^^^\n  File \"c:\\Users\\joeyi\\AppData\\Local\\Programs\\Python\\Python311\\Lib\\site-packages\\keras_tuner\\src\\tuners\\hyperband.py\", line 427, in run_trial\n    return super().run_trial(trial, *fit_args, **fit_kwargs)\n           ^^^^^^^^^^^^^^^^^^^^^^^^^^^^^^^^^^^^^^^^^^^^^^^^^\n  File \"c:\\Users\\joeyi\\AppData\\Local\\Programs\\Python\\Python311\\Lib\\site-packages\\keras_tuner\\src\\engine\\tuner.py\", line 314, in run_trial\n    obj_value = self._build_and_fit_model(trial, *args, **copied_kwargs)\n                ^^^^^^^^^^^^^^^^^^^^^^^^^^^^^^^^^^^^^^^^^^^^^^^^^^^^^^^^\n  File \"c:\\Users\\joeyi\\AppData\\Local\\Programs\\Python\\Python311\\Lib\\site-packages\\keras_tuner\\src\\engine\\tuner.py\", line 233, in _build_and_fit_model\n    results = self.hypermodel.fit(hp, model, *args, **kwargs)\n              ^^^^^^^^^^^^^^^^^^^^^^^^^^^^^^^^^^^^^^^^^^^^^^^\n  File \"c:\\Users\\joeyi\\AppData\\Local\\Programs\\Python\\Python311\\Lib\\site-packages\\keras_tuner\\src\\engine\\hypermodel.py\", line 149, in fit\n    return model.fit(*args, **kwargs)\n           ^^^^^^^^^^^^^^^^^^^^^^^^^^\n  File \"c:\\Users\\joeyi\\AppData\\Local\\Programs\\Python\\Python311\\Lib\\site-packages\\keras\\utils\\traceback_utils.py\", line 70, in error_handler\n    raise e.with_traceback(filtered_tb) from None\n  File \"C:\\Users\\joeyi\\AppData\\Local\\Temp\\__autograph_generated_filer0bbe969.py\", line 18, in tf__train_function\n    raise\nValueError: in user code:\n\n    File \"c:\\Users\\joeyi\\AppData\\Local\\Programs\\Python\\Python311\\Lib\\site-packages\\keras\\engine\\training.py\", line 1284, in train_function  *\n        return step_function(self, iterator)\n    File \"c:\\Users\\joeyi\\AppData\\Local\\Programs\\Python\\Python311\\Lib\\site-packages\\keras\\engine\\training.py\", line 1268, in step_function  **\n        outputs = model.distribute_strategy.run(run_step, args=(data,))\n    File \"c:\\Users\\joeyi\\AppData\\Local\\Programs\\Python\\Python311\\Lib\\site-packages\\keras\\engine\\training.py\", line 1249, in run_step  **\n        outputs = model.train_step(data)\n    File \"c:\\Users\\joeyi\\AppData\\Local\\Programs\\Python\\Python311\\Lib\\site-packages\\keras\\engine\\training.py\", line 1050, in train_step\n        y_pred = self(x, training=True)\n    File \"c:\\Users\\joeyi\\AppData\\Local\\Programs\\Python\\Python311\\Lib\\site-packages\\keras\\utils\\traceback_utils.py\", line 70, in error_handler\n        raise e.with_traceback(filtered_tb) from None\n    File \"c:\\Users\\joeyi\\AppData\\Local\\Programs\\Python\\Python311\\Lib\\site-packages\\keras\\engine\\input_spec.py\", line 235, in assert_input_compatibility\n        raise ValueError(\n\n    ValueError: Exception encountered when calling layer 'sequential' (type Sequential).\n    \n    Input 0 of layer \"gru\" is incompatible with the layer: expected ndim=3, found ndim=2. Full shape received: (None, 12)\n    \n    Call arguments received by layer 'sequential' (type Sequential):\n      \u2022 inputs=tf.Tensor(shape=(None, 12), dtype=float32)\n      \u2022 training=True\n      \u2022 mask=None\n\n"}